2025-08-05 11:07:30,237 - main - INFO - Health check passed in 4.84ms
2025-08-05 11:12:01,754 - main - INFO - Using database: sqlite:///app.db
2025-08-05 11:12:51,389 - main - INFO - Using database: sqlite:///app.db
2025-08-05 11:15:08,472 - main - INFO - Using database: sqlite:///app.db
2025-08-05 11:17:54,605 - main - INFO - Using database: sqlite:///app.db
2025-08-05 11:43:43,832 - main - INFO - Using database: postgresql://user:***@localhost:5432/mydb
2025-08-05 11:43:56,407 - main - INFO - Using database: postgresql://user:***@localhost:5432/mydb
2025-08-05 11:52:17,971 - main - INFO - Using database: postgresql://user:***@localhost:5432/mydb
2025-08-05 11:52:18,069 - main - INFO - Starting web server on port 8080
2025-08-05 11:52:18,069 - main - INFO - Starting web server on port 8080
2025-08-05 11:52:56,739 - main - ERROR - Health check FAILED in 4.35ms. Errors: {'database': {'status': 'error', 'message': 'Database timeout: (psycopg2.OperationalError) connection to server at "localhost" (127.0.0.1), port 5432 failed: Connection refused\n\tIs the server running on that host and accepting TCP/IP connections?\n\n(Background on this error at: https://sqlalche.me/e/20/e3q8)'}}
2025-08-05 11:52:56,739 - main - ERROR - Health check FAILED in 4.35ms. Errors: {'database': {'status': 'error', 'message': 'Database timeout: (psycopg2.OperationalError) connection to server at "localhost" (127.0.0.1), port 5432 failed: Connection refused\n\tIs the server running on that host and accepting TCP/IP connections?\n\n(Background on this error at: https://sqlalche.me/e/20/e3q8)'}}
2025-08-06 00:07:09,343 - main - INFO - Using database: postgresql://user:***@localhost:5432/mydb
2025-08-06 00:08:45,446 - main - INFO - Using database: sqlite:///app.db
2025-08-06 02:31:01,106 - main - INFO - Using database: sqlite:///app.db
2025-08-06 02:31:03,180 - ai_processing - ERROR - Database health check failed: db
2025-08-06 02:31:03,529 - main - ERROR - Health check FAILED in 349.03ms. Errors: {'database': {'status': 'error', 'message': 'Database error: db'}}
2025-08-06 02:31:03,529 - main - ERROR - Health check FAILED in 349.03ms. Errors: {'database': {'status': 'error', 'message': 'Database error: db'}}
2025-08-06 02:32:45,989 - main - INFO - Using database: sqlite:///app.db
2025-08-06 02:32:48,068 - ai_processing - ERROR - Database health check failed: db
2025-08-06 02:32:48,404 - main - ERROR - Health check FAILED in 335.74ms. Errors: {'database': {'status': 'error', 'message': 'Database error: db'}}
2025-08-06 02:32:48,404 - main - ERROR - Health check FAILED in 335.74ms. Errors: {'database': {'status': 'error', 'message': 'Database error: db'}}
2025-08-06 03:29:36,208 - main - INFO - Using database: postgresql://user:password@localhost:5432/mydb
2025-08-06 03:30:58,876 - main - ERROR - Health check FAILED in 486.9ms. Errors: {'database': {'status': 'error', 'message': 'Database timeout: (psycopg2.OperationalError) connection to server at "localhost" (127.0.0.1), port 5432 failed: Connection refused\n\tIs the server running on that host and accepting TCP/IP connections?\n\n(Background on this error at: https://sqlalche.me/e/20/e3q8)'}}
2025-08-06 03:30:58,876 - main - ERROR - Health check FAILED in 486.9ms. Errors: {'database': {'status': 'error', 'message': 'Database timeout: (psycopg2.OperationalError) connection to server at "localhost" (127.0.0.1), port 5432 failed: Connection refused\n\tIs the server running on that host and accepting TCP/IP connections?\n\n(Background on this error at: https://sqlalche.me/e/20/e3q8)'}}
2025-08-06 03:33:01,840 - main - INFO - Using database: sqlite:///app.db
2025-08-06 03:34:17,283 - main - INFO - Using database: sqlite:///app.db
2025-08-06 03:34:38,195 - main - ERROR - Health check FAILED in 351.93ms. Errors: {'database': {'status': 'error', 'message': 'Database timeout: (psycopg2.OperationalError) connection to server at "localhost" (127.0.0.1), port 5432 failed: Connection refused\n\tIs the server running on that host and accepting TCP/IP connections?\n\n(Background on this error at: https://sqlalche.me/e/20/e3q8)'}}
2025-08-06 03:34:38,195 - main - ERROR - Health check FAILED in 351.93ms. Errors: {'database': {'status': 'error', 'message': 'Database timeout: (psycopg2.OperationalError) connection to server at "localhost" (127.0.0.1), port 5432 failed: Connection refused\n\tIs the server running on that host and accepting TCP/IP connections?\n\n(Background on this error at: https://sqlalche.me/e/20/e3q8)'}}
2025-08-06 03:35:54,931 - main - INFO - Using database: sqlite:///app.db
2025-08-06 03:37:08,330 - main - INFO - Health check passed in 438.05ms
2025-08-06 03:37:08,330 - main - INFO - Health check passed in 438.05ms
2025-08-07 04:06:15,515 - main - INFO - Using database: sqlite:///app.db
2025-08-07 04:14:23,646 - main - INFO - Using database: sqlite:///app.db
2025-08-07 04:16:36,319 - main - INFO - Using database: sqlite:///app.db
2025-08-07 10:41:39,179 - main - INFO - Using database: postgresql://appuser:password@localhost:5432/mydb
2025-08-07 11:24:00,326 - main - INFO - Using database: postgresql://appuser:password@localhost:5432/mydb
2025-08-07 11:24:48,762 - main - INFO - Using database: postgresql://appuser:password@localhost:5432/mydb
2025-08-07 11:25:04,373 - main - INFO - Using database: postgresql://appuser:password@localhost:5432/mydb
2025-08-09 22:31:09,961 - main - INFO - Using database: postgresql://appuser:password@localhost:5432/mydb
2025-08-10 00:25:40,436 - main - INFO - Using database: postgresql://appuser:password@localhost:5432/mydb
2025-08-10 01:59:50,784 - main - INFO - Using database: postgresql://appuser:password@localhost:5432/mydb
2025-08-11 00:26:40,916 - main - INFO - Using database: postgresql://appuser:password@localhost:5432/mydb
2025-08-11 00:28:29,186 - main - INFO - Using database: postgresql://appuser:password@localhost:5432/mydb
2025-08-11 00:28:45,839 - main - INFO - Using database: postgresql://appuser:password@localhost:5432/mydb
2025-08-11 00:29:31,840 - main - INFO - Using database: sqlite:///app.db
2025-08-11 00:29:38,805 - main - INFO - Using database: sqlite:///app.db
2025-08-11 00:31:21,728 - main - INFO - Using database: sqlite:///app.db
2025-08-11 00:31:51,041 - main - INFO - Using database: sqlite:///app.db
2025-08-11 00:31:52,019 - main - INFO - Using database: sqlite:///app.db
2025-08-11 00:31:52,298 - werkzeug - WARNING -  * Debugger is active!
2025-08-11 00:32:59,804 - ai_processing - ERROR - Database health check failed: 'NullPool' object has no attribute 'size'
2025-08-11 00:33:02,755 - main - ERROR - Health check FAILED in 2969.44ms. Errors: {'database': {'status': 'error', 'message': "Database error: 'NullPool' object has no attribute 'size'"}, 'disk': {'status': 'error', 'message': 'Disk check failed: argument 1 (impossible<bad format char>)'}, 'ssl': {'status': 'error', 'message': 'SSL certificate check failed for smartdisputecanada.me: [SSL: SSLV3_ALERT_HANDSHAKE_FAILURE] sslv3 alert handshake failure (_ssl.c:1035)'}}
2025-08-11 00:33:02,755 - main - ERROR - Health check FAILED in 2969.44ms. Errors: {'database': {'status': 'error', 'message': "Database error: 'NullPool' object has no attribute 'size'"}, 'disk': {'status': 'error', 'message': 'Disk check failed: argument 1 (impossible<bad format char>)'}, 'ssl': {'status': 'error', 'message': 'SSL certificate check failed for smartdisputecanada.me: [SSL: SSLV3_ALERT_HANDSHAKE_FAILURE] sslv3 alert handshake failure (_ssl.c:1035)'}}
2025-08-11 00:33:06,853 - utils.error_handling - ERROR - Application Error: {'timestamp': '2025-08-11T04:33:06.850137', 'error_type': 'TemplateNotFound', 'error_message': 'auth/register.html', 'traceback': 'Traceback (most recent call last):\n  File "C:\\Users\\Easyhome\\AppData\\Local\\Packages\\PythonSoftwareFoundation.Python.3.13_qbz5n2kfra8p0\\LocalCache\\local-packages\\Python313\\site-packages\\flask\\app.py", line 1484, in full_dispatch_request\n    rv = self.dispatch_request()\n  File "C:\\Users\\Easyhome\\AppData\\Local\\Packages\\PythonSoftwareFoundation.Python.3.13_qbz5n2kfra8p0\\LocalCache\\local-packages\\Python313\\site-packages\\flask\\app.py", line 1469, in dispatch_request\n    return self.ensure_sync(self.view_functions[rule.endpoint])(**view_args)\n           ~~~~~~~~~~~~~~~~~~~~~~~~~~~~~~~~~~~~~~~~~~~~~~~~~~~~^^^^^^^^^^^^^\n  File "c:\\Users\\Easyhome\\Smart-Dispute-Flask-App\\routes\\auth_routes.py", line 80, in register\n    return render_template(\'auth/register.html\')\n  File "C:\\Users\\Easyhome\\AppData\\Local\\Packages\\PythonSoftwareFoundation.Python.3.13_qbz5n2kfra8p0\\LocalCache\\local-packages\\Python313\\site-packages\\flask\\templating.py", line 150, in render_template\n    template = app.jinja_env.get_or_select_template(template_name_or_list)\n  File "C:\\Users\\Easyhome\\AppData\\Local\\Packages\\PythonSoftwareFoundation.Python.3.13_qbz5n2kfra8p0\\LocalCache\\local-packages\\Python313\\site-packages\\jinja2\\environment.py", line 1087, in get_or_select_template\n    return self.get_template(template_name_or_list, parent, globals)\n           ~~~~~~~~~~~~~~~~~^^^^^^^^^^^^^^^^^^^^^^^^^^^^^^^^^^^^^^^^\n  File "C:\\Users\\Easyhome\\AppData\\Local\\Packages\\PythonSoftwareFoundation.Python.3.13_qbz5n2kfra8p0\\LocalCache\\local-packages\\Python313\\site-packages\\jinja2\\environment.py", line 1016, in get_template\n    return self._load_template(name, globals)\n           ~~~~~~~~~~~~~~~~~~~^^^^^^^^^^^^^^^\n  File "C:\\Users\\Easyhome\\AppData\\Local\\Packages\\PythonSoftwareFoundation.Python.3.13_qbz5n2kfra8p0\\LocalCache\\local-packages\\Python313\\site-packages\\jinja2\\environment.py", line 975, in _load_template\n    template = self.loader.load(self, name, self.make_globals(globals))\n  File "C:\\Users\\Easyhome\\AppData\\Local\\Packages\\PythonSoftwareFoundation.Python.3.13_qbz5n2kfra8p0\\LocalCache\\local-packages\\Python313\\site-packages\\jinja2\\loaders.py", line 126, in load\n    source, filename, uptodate = self.get_source(environment, name)\n                                 ~~~~~~~~~~~~~~~^^^^^^^^^^^^^^^^^^^\n  File "C:\\Users\\Easyhome\\AppData\\Local\\Packages\\PythonSoftwareFoundation.Python.3.13_qbz5n2kfra8p0\\LocalCache\\local-packages\\Python313\\site-packages\\flask\\templating.py", line 64, in get_source\n    return self._get_source_fast(environment, template)\n           ~~~~~~~~~~~~~~~~~~~~~^^^^^^^^^^^^^^^^^^^^^^^\n  File "C:\\Users\\Easyhome\\AppData\\Local\\Packages\\PythonSoftwareFoundation.Python.3.13_qbz5n2kfra8p0\\LocalCache\\local-packages\\Python313\\site-packages\\flask\\templating.py", line 98, in _get_source_fast\n    raise TemplateNotFound(template)\njinja2.exceptions.TemplateNotFound: auth/register.html\n', 'context': {'unhandled_exception': True}, 'user_id': None, 'request_path': '/register', 'request_method': 'GET', 'user_agent': 'python-requests/2.31.0'}
2025-08-11 00:34:49,238 - main - INFO - Using database: sqlite:///app.db
2025-08-11 00:34:49,413 - werkzeug - WARNING -  * Debugger is active!
2025-08-11 00:35:01,814 - ai_processing - ERROR - Database health check failed: 'NullPool' object has no attribute 'size'
2025-08-11 00:35:03,791 - main - ERROR - Health check FAILED in 1991.99ms. Errors: {'database': {'status': 'error', 'message': "Database error: 'NullPool' object has no attribute 'size'"}, 'disk': {'status': 'error', 'message': 'Disk check failed: argument 1 (impossible<bad format char>)'}, 'ssl': {'status': 'error', 'message': 'SSL certificate check failed for smartdisputecanada.me: [SSL: SSLV3_ALERT_HANDSHAKE_FAILURE] sslv3 alert handshake failure (_ssl.c:1035)'}}
2025-08-11 13:53:00,976 - main - INFO - Using database: postgresql://smartdispute_user:smartdispute_password@db:5432/smartdispute_db
2025-08-11 13:53:02,419 - main - INFO - Using database: postgresql://smartdispute_user:smartdispute_password@db:5432/smartdispute_db
2025-08-11 13:53:03,737 - main - INFO - Using database: postgresql://smartdispute_user:smartdispute_password@db:5432/smartdispute_db
2025-08-11 13:53:05,273 - main - INFO - Using database: postgresql://smartdispute_user:smartdispute_password@db:5432/smartdispute_db
2025-08-11 13:53:07,155 - main - INFO - Using database: postgresql://smartdispute_user:smartdispute_password@db:5432/smartdispute_db
2025-08-11 13:53:09,812 - main - INFO - Using database: postgresql://smartdispute_user:smartdispute_password@db:5432/smartdispute_db
2025-08-11 13:53:14,076 - main - INFO - Using database: postgresql://smartdispute_user:smartdispute_password@db:5432/smartdispute_db
2025-08-11 13:53:21,522 - main - INFO - Using database: postgresql://smartdispute_user:smartdispute_password@db:5432/smartdispute_db
2025-08-11 13:53:35,321 - main - INFO - Using database: postgresql://smartdispute_user:smartdispute_password@db:5432/smartdispute_db
2025-08-11 13:54:01,855 - main - INFO - Using database: postgresql://smartdispute_user:smartdispute_password@db:5432/smartdispute_db
2025-08-11 13:54:54,087 - main - INFO - Using database: postgresql://smartdispute_user:smartdispute_password@db:5432/smartdispute_db
2025-08-11 13:55:55,165 - main - INFO - Using database: postgresql://smartdispute_user:smartdispute_password@db:5432/smartdispute_db
2025-08-11 13:56:56,139 - main - INFO - Using database: postgresql://smartdispute_user:smartdispute_password@db:5432/smartdispute_db
2025-08-11 13:57:57,214 - main - INFO - Using database: postgresql://smartdispute_user:smartdispute_password@db:5432/smartdispute_db
